<?xml version="1.0" encoding="UTF-8"?>
<!-- Generated by org.testng.reporters.JUnitXMLReporter -->
<testsuite hostname="stray" name="Default test" tests="2" failures="2" timestamp="12 Oct 2015 07:39:17 GMT" time="0.071" errors="0">
  <testcase name="testAssert1" time="0.03" classname="com.danlu.demo_assert.DemoAssert">
    <failure type="java.lang.Throwable">
      <![CDATA[java.lang.Throwable
	at message : expected [3] but found [2] in method : .testAssert1(DemoAssert:11)
	at com.danlu.demo_assert.DemoAssert.testAssert1(DemoAssert.java:11)
]]>
    </failure>
  </testcase> <!-- testAssert1 -->
  <testcase name="testAssert2" time="0.002" classname="com.danlu.demo_assert.DemoAssert">
    <failure type="java.lang.Throwable">
      <![CDATA[java.lang.Throwable
	at message : xyz expected [3] but found [2] in method : .testAssert2(DemoAssert:18)
	at com.danlu.demo_assert.DemoAssert.testAssert2(DemoAssert.java:18)
]]>
    </failure>
  </testcase> <!-- testAssert2 -->
</testsuite> <!-- Default test -->
