<?xml version="1.0" encoding="UTF-8"?>
<!-- Generated by org.testng.reporters.JUnitReportReporter -->
<testsuite hostname="stray" name="com.danlu.demo_assert.DemoAssert" tests="2" failures="0" timestamp="12 Oct 2015 07:39:18 GMT" time="0.032" errors="2">
  <testcase name="testAssert2" time="0.002" classname="com.danlu.demo_assert.DemoAssert">
    <error type="java.lang.Throwable">
      <![CDATA[java.lang.Throwable
	at message : xyz expected [3] but found [2] in method : .testAssert2(DemoAssert:18)
	at com.danlu.demo_assert.DemoAssert.testAssert2(DemoAssert.java:18)
]]>
    </error>
  </testcase> <!-- testAssert2 -->
  <testcase name="testAssert1" time="0.030" classname="com.danlu.demo_assert.DemoAssert">
    <error type="java.lang.Throwable">
      <![CDATA[java.lang.Throwable
	at message : expected [3] but found [2] in method : .testAssert1(DemoAssert:11)
	at com.danlu.demo_assert.DemoAssert.testAssert1(DemoAssert.java:11)
]]>
    </error>
  </testcase> <!-- testAssert1 -->
</testsuite> <!-- com.danlu.demo_assert.DemoAssert -->
